Traceback (most recent call last):
  File "/home/sharad/miniconda3/envs/unearthed-challenge-name/lib/python3.7/site-packages/urllib3/connectionpool.py", line 706, in urlopen
    chunked=chunked,
  File "/home/sharad/miniconda3/envs/unearthed-challenge-name/lib/python3.7/site-packages/urllib3/connectionpool.py", line 394, in _make_request
    conn.request(method, url, **httplib_request_kw)
  File "/home/sharad/miniconda3/envs/unearthed-challenge-name/lib/python3.7/http/client.py", line 1281, in request
    self._send_request(method, url, body, headers, encode_chunked)
  File "/home/sharad/miniconda3/envs/unearthed-challenge-name/lib/python3.7/http/client.py", line 1327, in _send_request
    self.endheaders(body, encode_chunked=encode_chunked)
  File "/home/sharad/miniconda3/envs/unearthed-challenge-name/lib/python3.7/http/client.py", line 1276, in endheaders
    self._send_output(message_body, encode_chunked=encode_chunked)
  File "/home/sharad/miniconda3/envs/unearthed-challenge-name/lib/python3.7/http/client.py", line 1036, in _send_output
    self.send(msg)
  File "/home/sharad/miniconda3/envs/unearthed-challenge-name/lib/python3.7/http/client.py", line 976, in send
    self.connect()
  File "/home/sharad/miniconda3/envs/unearthed-challenge-name/lib/python3.7/site-packages/docker/transport/unixconn.py", line 43, in connect
    sock.connect(self.unix_socket)
FileNotFoundError: [Errno 2] No such file or directory

During handling of the above exception, another exception occurred:

Traceback (most recent call last):
  File "/home/sharad/miniconda3/envs/unearthed-challenge-name/lib/python3.7/site-packages/requests/adapters.py", line 449, in send
    timeout=timeout
  File "/home/sharad/miniconda3/envs/unearthed-challenge-name/lib/python3.7/site-packages/urllib3/connectionpool.py", line 756, in urlopen
    method, url, error=e, _pool=self, _stacktrace=sys.exc_info()[2]
  File "/home/sharad/miniconda3/envs/unearthed-challenge-name/lib/python3.7/site-packages/urllib3/util/retry.py", line 532, in increment
    raise six.reraise(type(error), error, _stacktrace)
  File "/home/sharad/miniconda3/envs/unearthed-challenge-name/lib/python3.7/site-packages/urllib3/packages/six.py", line 769, in reraise
    raise value.with_traceback(tb)
  File "/home/sharad/miniconda3/envs/unearthed-challenge-name/lib/python3.7/site-packages/urllib3/connectionpool.py", line 706, in urlopen
    chunked=chunked,
  File "/home/sharad/miniconda3/envs/unearthed-challenge-name/lib/python3.7/site-packages/urllib3/connectionpool.py", line 394, in _make_request
    conn.request(method, url, **httplib_request_kw)
  File "/home/sharad/miniconda3/envs/unearthed-challenge-name/lib/python3.7/http/client.py", line 1281, in request
    self._send_request(method, url, body, headers, encode_chunked)
  File "/home/sharad/miniconda3/envs/unearthed-challenge-name/lib/python3.7/http/client.py", line 1327, in _send_request
    self.endheaders(body, encode_chunked=encode_chunked)
  File "/home/sharad/miniconda3/envs/unearthed-challenge-name/lib/python3.7/http/client.py", line 1276, in endheaders
    self._send_output(message_body, encode_chunked=encode_chunked)
  File "/home/sharad/miniconda3/envs/unearthed-challenge-name/lib/python3.7/http/client.py", line 1036, in _send_output
    self.send(msg)
  File "/home/sharad/miniconda3/envs/unearthed-challenge-name/lib/python3.7/http/client.py", line 976, in send
    self.connect()
  File "/home/sharad/miniconda3/envs/unearthed-challenge-name/lib/python3.7/site-packages/docker/transport/unixconn.py", line 43, in connect
    sock.connect(self.unix_socket)
urllib3.exceptions.ProtocolError: ('Connection aborted.', FileNotFoundError(2, 'No such file or directory'))

During handling of the above exception, another exception occurred:

Traceback (most recent call last):
  File "/home/sharad/miniconda3/envs/unearthed-challenge-name/lib/python3.7/site-packages/docker/api/client.py", line 214, in _retrieve_server_version
    return self.version(api_version=False)["ApiVersion"]
  File "/home/sharad/miniconda3/envs/unearthed-challenge-name/lib/python3.7/site-packages/docker/api/daemon.py", line 181, in version
    return self._result(self._get(url), json=True)
  File "/home/sharad/miniconda3/envs/unearthed-challenge-name/lib/python3.7/site-packages/docker/utils/decorators.py", line 46, in inner
    return f(self, *args, **kwargs)
  File "/home/sharad/miniconda3/envs/unearthed-challenge-name/lib/python3.7/site-packages/docker/api/client.py", line 237, in _get
    return self.get(url, **self._set_request_timeout(kwargs))
  File "/home/sharad/miniconda3/envs/unearthed-challenge-name/lib/python3.7/site-packages/requests/sessions.py", line 555, in get
    return self.request('GET', url, **kwargs)
  File "/home/sharad/miniconda3/envs/unearthed-challenge-name/lib/python3.7/site-packages/requests/sessions.py", line 542, in request
    resp = self.send(prep, **send_kwargs)
  File "/home/sharad/miniconda3/envs/unearthed-challenge-name/lib/python3.7/site-packages/requests/sessions.py", line 655, in send
    r = adapter.send(request, **kwargs)
  File "/home/sharad/miniconda3/envs/unearthed-challenge-name/lib/python3.7/site-packages/requests/adapters.py", line 498, in send
    raise ConnectionError(err, request=request)
requests.exceptions.ConnectionError: ('Connection aborted.', FileNotFoundError(2, 'No such file or directory'))

During handling of the above exception, another exception occurred:

Traceback (most recent call last):
  File "/home/sharad/miniconda3/envs/unearthed-challenge-name/lib/python3.7/site-packages/unearthed/cli/docker.py", line 59, in docker_run
    pull_image(docker_image)
  File "/home/sharad/miniconda3/envs/unearthed-challenge-name/lib/python3.7/site-packages/unearthed/cli/docker.py", line 32, in pull_image
    client = docker.from_env()
  File "/home/sharad/miniconda3/envs/unearthed-challenge-name/lib/python3.7/site-packages/docker/client.py", line 101, in from_env
    **kwargs_from_env(**kwargs)
  File "/home/sharad/miniconda3/envs/unearthed-challenge-name/lib/python3.7/site-packages/docker/client.py", line 45, in __init__
    self.api = APIClient(*args, **kwargs)
  File "/home/sharad/miniconda3/envs/unearthed-challenge-name/lib/python3.7/site-packages/docker/api/client.py", line 197, in __init__
    self._version = self._retrieve_server_version()
  File "/home/sharad/miniconda3/envs/unearthed-challenge-name/lib/python3.7/site-packages/docker/api/client.py", line 222, in _retrieve_server_version
    'Error while fetching server API version: {0}'.format(e)
docker.errors.DockerException: Error while fetching server API version: ('Connection aborted.', FileNotFoundError(2, 'No such file or directory'))
