Traceback (most recent call last):
  File "/home/sharad/miniconda3/envs/unearthed-challenge-name/lib/python3.7/site-packages/urllib3/connection.py", line 170, in _new_conn
    (self._dns_host, self.port), self.timeout, **extra_kw
  File "/home/sharad/miniconda3/envs/unearthed-challenge-name/lib/python3.7/site-packages/urllib3/util/connection.py", line 96, in create_connection
    raise err
  File "/home/sharad/miniconda3/envs/unearthed-challenge-name/lib/python3.7/site-packages/urllib3/util/connection.py", line 86, in create_connection
    sock.connect(sa)
OSError: [Errno 101] Network is unreachable

During handling of the above exception, another exception occurred:

Traceback (most recent call last):
  File "/home/sharad/miniconda3/envs/unearthed-challenge-name/lib/python3.7/site-packages/urllib3/connectionpool.py", line 706, in urlopen
    chunked=chunked,
  File "/home/sharad/miniconda3/envs/unearthed-challenge-name/lib/python3.7/site-packages/urllib3/connectionpool.py", line 382, in _make_request
    self._validate_conn(conn)
  File "/home/sharad/miniconda3/envs/unearthed-challenge-name/lib/python3.7/site-packages/urllib3/connectionpool.py", line 1010, in _validate_conn
    conn.connect()
  File "/home/sharad/miniconda3/envs/unearthed-challenge-name/lib/python3.7/site-packages/urllib3/connection.py", line 353, in connect
    conn = self._new_conn()
  File "/home/sharad/miniconda3/envs/unearthed-challenge-name/lib/python3.7/site-packages/urllib3/connection.py", line 182, in _new_conn
    self, "Failed to establish a new connection: %s" % e
urllib3.exceptions.NewConnectionError: <urllib3.connection.HTTPSConnection object at 0x7fb3378d8610>: Failed to establish a new connection: [Errno 101] Network is unreachable

During handling of the above exception, another exception occurred:

Traceback (most recent call last):
  File "/home/sharad/miniconda3/envs/unearthed-challenge-name/lib/python3.7/site-packages/requests/adapters.py", line 449, in send
    timeout=timeout
  File "/home/sharad/miniconda3/envs/unearthed-challenge-name/lib/python3.7/site-packages/urllib3/connectionpool.py", line 756, in urlopen
    method, url, error=e, _pool=self, _stacktrace=sys.exc_info()[2]
  File "/home/sharad/miniconda3/envs/unearthed-challenge-name/lib/python3.7/site-packages/urllib3/util/retry.py", line 574, in increment
    raise MaxRetryError(_pool, url, error or ResponseError(cause))
urllib3.exceptions.MaxRetryError: HTTPSConnectionPool(host='crowdml.unearthed.solutions', port=443): Max retries exceeded with url: /challenges/e18ed31f-c11b-420f-b4f8-6407cf578da2/submission (Caused by NewConnectionError('<urllib3.connection.HTTPSConnection object at 0x7fb3378d8610>: Failed to establish a new connection: [Errno 101] Network is unreachable'))

During handling of the above exception, another exception occurred:

Traceback (most recent call last):
  File "/home/sharad/miniconda3/envs/unearthed-challenge-name/lib/python3.7/site-packages/unearthed/cli/commands/submit.py", line 46, in submit
    submission = Submission.fromApi(challenge.challengeId)
  File "/home/sharad/miniconda3/envs/unearthed-challenge-name/lib/python3.7/site-packages/unearthed/core/models/submission.py", line 63, in fromApi
    response = requests.post(url=url, auth=auth_handler, timeout=10)
  File "/home/sharad/miniconda3/envs/unearthed-challenge-name/lib/python3.7/site-packages/requests/api.py", line 117, in post
    return request('post', url, data=data, json=json, **kwargs)
  File "/home/sharad/miniconda3/envs/unearthed-challenge-name/lib/python3.7/site-packages/requests/api.py", line 61, in request
    return session.request(method=method, url=url, **kwargs)
  File "/home/sharad/miniconda3/envs/unearthed-challenge-name/lib/python3.7/site-packages/requests/sessions.py", line 542, in request
    resp = self.send(prep, **send_kwargs)
  File "/home/sharad/miniconda3/envs/unearthed-challenge-name/lib/python3.7/site-packages/requests/sessions.py", line 655, in send
    r = adapter.send(request, **kwargs)
  File "/home/sharad/miniconda3/envs/unearthed-challenge-name/lib/python3.7/site-packages/requests/adapters.py", line 516, in send
    raise ConnectionError(e, request=request)
requests.exceptions.ConnectionError: HTTPSConnectionPool(host='crowdml.unearthed.solutions', port=443): Max retries exceeded with url: /challenges/e18ed31f-c11b-420f-b4f8-6407cf578da2/submission (Caused by NewConnectionError('<urllib3.connection.HTTPSConnection object at 0x7fb3378d8610>: Failed to establish a new connection: [Errno 101] Network is unreachable'))
